Workbook
Name Slicer_Assigned_To: #N/A
Name Slicer_Department: #N/A
Name Slicer_Priority: #N/A
Name Slicer_Task_Status: #N/A

Sheet Raw_Data
A1: Task ID | B1: Project Name | C1: Department | D1: Assigned To | E1: Role | F1: Priority | G1: Task Category | H1: Start Date | I1: Due Date | J1: Completion Date | K1: Task Status | L1: Progress % | M1: Estimated Hours | N1: Actual Hours | O1: Variance | P1: Remarks
A2: TSK-0001 | B2: CRM Migration | C2: IT | D2: Pooja Reddy | E2: Manager | F2: HIGH | G2: Research | H2: 45367 | I2: 45419 | J2: 45430 | K2: COMPLETED | L2: 100 | M2: 10.6 | N2: 12.5 | P2: Waiting for client feedback
A3: TSK-0002 | B3: Product Launch | C3: Sales | D3: Ananya Das | E3: Analyst | F3: Low | G3: design | H3: 45662 | I3: 45708 | K3: on hold | M3: 48.8
A4: TSK-0003 | B4: Marketing Campaign | C4: HR | D4: Vikram Singh | E4: developer | F4: HIGH | G4: planning | H4: 45348 | I4: 45358 | K4: On Hold | M4: 68.4 | P4: Resource conflict
A5: TSK-0004 | B5: Data Analytics Platform | C5: Finance | D5: Karan Malhotra | E5: tester | F5: high | G5: Planning | H5: 45617 | I5: 45661 | K5: NOT STARTED | M5: 18.6 | P5: Need more resources
A6: TSK-0005 | B6: Employee Onboarding | C6: it | D6: Meera Thakur | E6: manager | F6: critical | G6: Testing | H6: 45490 | I6: 45512 | K6: On Hold | L6: 28 | M6: 32.1 | P6: final review stage
A7: TSK-0006 | B7: CRM Migration | C7: FINANCE | D7: Deepak Nair | E7: manager | F7: High | G7: documentation | H7: 45490 | I7: 45512 | K7: IN PROGRESS | L7: 73 | M7: 66.5 | N7: 25.2 | P7: On track
A8: TSK-0007 | B8: Mobile App v2 | C8: HR | D8: Sneha Gupta | E8: Lead | F8: Medium | G8: documentation | H8: 45369 | I8: 45390 | K8: In Progress | L8: 65% | M8: 60.8 | N8: 32.8 | P8: Stakeholder review next week
A9: TSK-0008 | B9: Annual Audit | C9: Sales | D9: Kavita Rao | E9: ANALYST | F9: Critical | G9: development | H9: 45352 | I9: 45366 | K9: in progress | M9: 33 | N9: 16.7 | P9: Priority shifted
A10: TSK-0009 | B10: CRM Migration | C10: HR | D10: Sanjay Kulkarni | E10: designer | F10: high | G10: Planning | H10: 45518 | I10: 45533 | K10: On Hold | M10: 70.6 | N10: 0 | P10: Rescheduled
A11: TSK-0010 | B11: Supply Chain Optimization | C11: Finance | D11: Meera Thakur | E11: Designer | F11: critical | G11: deployment | H11: 45607 | I11: 45624 | K11: In Progress | L11: 57 | M11: 49.5 | N11: 6.8 | P11: Stakeholder review next week
A12: TSK-0011 | B12: Product Launch | C12: IT | D12: Sneha Gupta | E12: ANALYST | F12: high | G12: Deployment | H12: 45331 | I12: 45384 | K12: In Progress | L12: 62 | M12: 24.1 | N12: 10.3 | P12: Almost done
A13: TSK-0012 | B13: Product Launch | C13: hr | D13: Arjun Mehta | E13: Tester | F13: MEDIUM | G13: deployment | H13: 45527 | I13: 45539 | K13: IN PROGRESS | L13: 38 | M13: 48.7 | P13: Needs QA sign-off
A14: TSK-0013 | B14: CRM Migration | C14: IT | D14: Sneha Gupta | E14: ANALYST | F14: Critical | G14: development | H14: 45465 | I14: 45474 | K14: cancelled | L14: 0 | M14: 25.2 | N14: 0 | P14: Almost done
A15: TSK-0014 | B15: Annual Audit | C15: sales | D15: Sneha Gupta | E15: Lead | F15: Critical | G15: Documentation | H15: 45393 | I15: 45404 | J15: 45415 | K15: COMPLETED | L15: 100% | M15: 30.9 | N15: 32.3 | P15: escalated to management
A16: TSK-0015 | B16: Website Redesign | C16: operations | D16: Pooja Reddy | E16: designer | F16: Critical | G16: Testing | H16: 45423 | I16: 45440 | K16: In Progress | M16: 17.9 | N16: 14.3 | P16: On track
A17: TSK-0016 | B17: Supply Chain Optimization | C17: Finance | D17: Rahul Sharma | E17: Analyst | F17: high | G17: Research | H17: 45381 | I17: 45412 | K17: Cancelled | M17: 20.2 | N17: 0 | P17: Need more resources
A18: TSK-0017 | B18: Marketing Campaign | C18: IT | D18: Arjun Mehta | E18: Manager | F18: Critical | G18: documentation | H18: 45442 | I18: 45474 | K18: Cancelled | L18: 0 | M18: 18.4 | P18: Need more resources
A19: TSK-0018 | B19: Supply Chain Optimization | C19: IT | D19: Pooja Reddy | E19: designer | F19: High | G19: development | H19: 45595 | I19: 45630 | K19: cancelled | M19: 16 | P19: On track
A20: TSK-0019 | B20: CRM Migration | C20: it | D20: Rohan Iyer | E20: manager | F20: Medium | G20: Testing | H20: 45587 | I20: 45607 | J20: 45616 | K20: completed | L20: 100 | M20: 35.9 | N20: 44.2 | P20: Rescheduled
A21: TSK-0020 | B21: Product Launch | C21: HR | D21: Sneha Gupta | E21: Manager | F21: Medium | G21: testing | H21: 45639 | I21: 45685 | K21: not started | M21: 28 | P21: Waiting for client feedback
A22: TSK-0021 | B22: Mobile App v2 | C22: Finance | D22: Priya Patel | E22: Manager | F22: Low | G22: research | H22: 45363 | I22: 45390 | J22: 45387 | K22: Completed | L22: 100 | M22: 25.7 | N22: 28.2 | P22: Priority shifted
A23: TSK-0022 | B23: Supply Chain Optimization | C23: IT | D23: Rohan Iyer | E23: Designer | F23: Critical | G23: Testing | H23: 45364 | I23: 45385 | J23: 45378 | K23: COMPLETED | L23: 100 | M23: 15.8 | N23: 12.1 | P23: Almost done
A24: TSK-0023 | B24: Employee Onboarding | C24: Sales | D24: Kavita Rao | E24: Manager | F24: Critical | G24: development | H24: 45343 | I24: 45388 | K24: on hold | L24: 22 | M24: 4.3 | P24: Waiting on approval
A25: TSK-0024 | B25: Annual Audit | C25: Sales | D25: Deepak Nair | E25: Coordinator | F25: Low | G25: Development | H25: 45353 | I25: 45362 | K25: In Progress | L25: 22 | M25: 36.7 | P25: Stakeholder review next week
A26: TSK-0025 | B26: IT Infrastructure | C26: Marketing | D26: Rohan Iyer | E26: manager | F26: Low | G26: Testing | H26: 45477 | I26: 45531 | K26: on hold | L26: 14 | M26: 69.7
A27: TSK-0026 | B27: Annual Audit | C27: HR | D27: Sanjay Kulkarni | E27: Coordinator | F27: Critical | G27: Research | H27: 45432 | I27: 45447 | J27: 45449 | K27: COMPLETED | L27: 100 | M27: 69.3 | N27: 63.2
A28: TSK-0027 | B28: Product Launch | C28: marketing | D28: Rahul Sharma | E28: Manager | F28: Medium | G28: planning | H28: 45438 | I28: 45498 | J28: 45512 | K28: Completed | L28: 100 | M28: 30.7 | N28: 36.1 | P28: final review stage
A29: TSK-0028 | B29: Website Redesign | C29: Finance | D29: Karan Malhotra | E29: Manager | F29: High | G29: research | H29: 45315 | I29: 45326 | K29: on hold | M29: 63.8 | N29: 0 | P29: Team capacity issue
A30: TSK-0029 | B30: CRM Migration | C30: operations | D30: Karan Malhotra | E30: Manager | F30: Medium | G30: development | H30: 45658 | I30: 45690 | J30: 45696 | K30: Completed | L30: 100 | M30: 56.2 | N30: 78.8 | P30: escalated to management
A31: TSK-0030 | B31: Marketing Campaign | C31: it | D31: Rohan Iyer | E31: designer | F31: low | G31: planning | H31: 45635 | I31: 45694 | J31: 45707 | K31: COMPLETED | L31: 100 | M31: 42.5 | N31: 54.2 | P31: Budget approved
A32: TSK-0031 | B32: Supply Chain Optimization | C32: finance | D32: Sneha Gupta | E32: Coordinator | F32: Low | G32: review | H32: 45642 | I32: 45694 | K32: in progress | M32: 45.6 | P32: Scope changed mid-sprint
A33: TSK-0032 | B33: Marketing Campaign | C33: HR | D33: Kavita Rao | E33: coordinator | F33: MEDIUM | G33: design | H33: 45557 | I33: 45592 | K33: in progress | L33: 62% | M33: 11.1 | N33: 3.9 | P33: Scope changed mid-sprint
A34: TSK-0033 | B34: Product Launch | C34: finance | D34: Rahul Sharma | E34: analyst | F34: HIGH | G34: Deployment | H34: 45608 | I34: 45667 | J34: 45671 | K34: Completed | L34: 100% | M34: 71.3 | N34: 79.3 | P34: no blockers
A35: TSK-0034 | B35: Marketing Campaign | C35: marketing | D35: Amit Verma | E35: Analyst | F35: Critical | G35: Testing | H35: 45694 | I35: 45726 | K35: IN PROGRESS | M35: 7.8 | P35: Delayed due to dependency
A36: TSK-0035 | B36: Annual Audit | C36: Sales | D36: Rohan Iyer | E36: lead | F36: Low | G36: planning | H36: 45682 | I36: 45715 | K36: cancelled | M36: 67.1
A37: TSK-0036 | B37: Data Analytics Platform | C37: Sales | D37: Vikram Singh | E37: manager | F37: critical | G37: research | H37: 45688 | I37: 45742 | K37: cancelled | M37: 51.6 | N37: 0
A38: TSK-0037 | B38: Employee Onboarding | C38: marketing | D38: Vikram Singh | E38: designer | F38: medium | G38: Development | H38: 45366 | I38: 45380 | K38: IN PROGRESS | L38: 64 | M38: 8.9 | N38: 5.3
A39: TSK-0038 | B39: Product Launch | C39: Operations | D39: Arjun Mehta | E39: Analyst | F39: critical | G39: review | H39: 45540 | I39: 45545 | K39: NOT STARTED | L39: 0 | M39: 61.3 | N39: 0 | P39: Priority shifted
A40: TSK-0039 | B40: Mobile App v2 | C40: marketing | D40: Kavita Rao | E40: manager | F40: Medium | G40: Documentation | H40: 45544 | I40: 45550 | K40: On Hold | M40: 55.6 | N40: 0 | P40: escalated to management
...

Sheet Lookup_Lists
A1: Messy_Priority | B1: Clean_Priority | D1: Messy_Status | E1: Clean_Status | G1: Messy_Department | H1: Clean_Department | J1: Messy_Category | K1: Clean_Category | M1: Messy_Role | N1: Clean_Role | P1: Valid_Priorities | Q1: Valid_Statuses | R1: Valid_Departments | S1: Valid_Categories | T1: Valid_Roles
A2: high | B2: High | D2: completed | E2: Completed | G2: IT | H2: IT | J2: Development | K2: Development | M2: Analyst | N2: Analyst | P2: Critical | Q2: Completed | R2: IT | S2: Development | T2: Analyst
A3: HIGH | B3: High | D3: COMPLETED | E3: Completed | G3: IT | H3: IT | J3: development | K3: Development | M3: analyst | N3: Analyst | P3: High | Q3: In Progress | R3: Finance | S3: Testing | T3: Developer
A4: High | B4: High | D4: Completed | E4: Completed | G4: it | H4: IT | J4: Development | K4: Development | M4: ANALYST | N4: Analyst | P4: Medium | Q4: Not Started | R4: Marketing | S4: Design | T4: Manager
A5: high | B5: High | D5: Completed | E5: Completed | G5: It | H5: IT | J5: Testing | K5: Testing | M5: analyst | N5: Analyst | P5: Low | Q5: On Hold | R5: HR | S5: Research | T5: Designer
A6: medium | B6: Medium | D6: completed | E6: Completed | G6: Finance | H6: Finance | J6: testing | K6: Testing | M6: Developer | N6: Developer | Q6: Cancelled | R6: Operations | S6: Planning | T6: Tester
A7: MEDIUM | B7: Medium | D7: in progress | E7: In Progress | G7: finance | H7: Finance | J7: testing | K7: Testing | M7: developer | N7: Developer | R7: Sales | S7: Review | T7: Coordinator
A8: Medium | B8: Medium | D8: IN PROGRESS | E8: In Progress | G8: FINANCE | H8: Finance | J8: Design | K8: Design | M8: Developer | N8: Developer | S8: Documentation | T8: Lead
A9: medium | B9: Medium | D9: In Progress | E9: In Progress | G9: finance | H9: Finance | J9: design | K9: Design | M9: DEVELOPER | N9: Developer | S9: Deployment
A10: low | B10: Low | D10: In Progress | E10: In Progress | G10: finance | H10: Finance | J10: DESIGN | K10: Design | M10: Manager | N10: Manager
A11: LOW | B11: Low | D11: in progress | E11: In Progress | G11: Marketing | H11: Marketing | J11: Research | K11: Research | M11: manager | N11: Manager
A12: Low | B12: Low | D12: not started | E12: Not Started | G12: marketing | H12: Marketing | J12: research | K12: Research | M12: Manager | N12: Manager
A13: low | B13: Low | D13: NOT STARTED | E13: Not Started | G13: MARKETING | H13: Marketing | J13: research | K13: Research | M13: MANAGER | N13: Manager
A14: critical | B14: Critical | D14: Not Started | E14: Not Started | G14: marketing | H14: Marketing | J14: Planning | K14: Planning | M14: Designer | N14: Designer
A15: CRITICAL | B15: Critical | D15: Not Started | E15: Not Started | G15: HR | H15: HR | J15: planning | K15: Planning | M15: designer | N15: Designer
A16: Critical | B16: Critical | D16: not started | E16: Not Started | G16: hr | H16: HR | J16: PLANNING | K16: Planning | M16: designer | N16: Designer
A17: critical | B17: Critical | D17: on hold | E17: On Hold | G17: HR | H17: HR | J17: Review | K17: Review | M17: Tester | N17: Tester
A18: High | B18: High | D18: ON HOLD | E18: On Hold | G18: hr | H18: HR | J18: review | K18: Review | M18: tester | N18: Tester
A19: Medium | B19: Medium | D19: On Hold | E19: On Hold | G19: Operations | H19: Operations | J19: review | K19: Review | M19: tester | N19: Tester
A20: Low | B20: Low | D20: On Hold | E20: On Hold | G20: operations | H20: Operations | J20: Documentation | K20: Documentation | M20: Coordinator | N20: Coordinator
A21: Critical | B21: Critical | D21: on hold | E21: On Hold | G21: Operations | H21: Operations | J21: documentation | K21: Documentation | M21: coordinator | N21: Coordinator
D22: cancelled | E22: Cancelled | G22: OPERATIONS | H22: Operations | J22: DOCUMENTATION | K22: Documentation | M22: COORDINATOR | N22: Coordinator
D23: CANCELLED | E23: Cancelled | G23: Sales | H23: Sales | J23: Deployment | K23: Deployment | M23: Lead | N23: Lead
D24: Cancelled | E24: Cancelled | G24: sales | H24: Sales | J24: deployment | K24: Deployment | M24: lead | N24: Lead
D25: Cancelled | E25: Cancelled | G25: Sales | H25: Sales | J25: deployment | K25: Deployment | M25: lead | N25: Lead
D26: cancelled | E26: Cancelled | G26: SALES | H26: Sales

Sheet Clean_Data
A1: Task ID | B1: Project Name | C1: Department | D1: Assigned To | E1: Role | F1: Priority | G1: Task Category | H1: Start Date | I1: Due Date | J1: Completion Date | K1: Task Status | L1: Progress % | M1: Estimated Hours | N1: Actual Hours | O1: Variance | P1: Remarks
A2: =TRIM(CLEAN(Raw_Data!A2)) -> TSK-0001 | B2: =TRIM(CLEAN(Raw_Data!B2)) -> CRM Migration | C2: =IFERROR(VLOOKUP(TRIM(CLEAN(Raw_Data!C2)),Lookup_Lists!$G:$H,2,FALSE()),TRIM(CLEAN(Raw_Data!C2))) -> IT | D2: =TRIM(CLEAN(Raw_Data!D2)) -> Pooja Reddy | E2: =IFERROR(VLOOKUP(TRIM(CLEAN(Raw_Data!E2)),Lookup_Lists!$M:$N,2,FALSE()),TRIM(CLEAN(Raw_Data!E2))) -> Manager | F2: =IFERROR(VLOOKUP(TRIM(CLEAN(Raw_Data!F2)),Lookup_Lists!$A:$B,2,FALSE()),TRIM(CLEAN(Raw_Data!F2))) -> High | G2: =IFERROR(VLOOKUP(TRIM(CLEAN(Raw_Data!G2)),Lookup_Lists!$J:$K,2,FALSE()),TRIM(CLEAN(Raw_Data!G2))) -> Research | H2: =IF(Raw_Data!H2="","",Raw_Data!H2) -> 45367 | I2: =IF(Raw_Data!I2="","",Raw_Data!I2) -> 45419 | J2: =IF(Raw_Data!J2="","",Raw_Data!J2) -> 45430 | K2: =IFERROR(VLOOKUP(TRIM(CLEAN(Raw_Data!K2)),Lookup_Lists!$D:$E,2,FALSE()),TRIM(CLEAN(Raw_Data!K2))) -> Completed | L2: =IF(TRIM(CLEAN(Raw_Data!L2))="","",IFERROR(MIN(100,MAX(0,VALUE(SUBSTITUTE(TRIM(CLEAN(Raw_Data!L2)),"%",""))))/100,0)) -> 1 | M2: =IFERROR(IF(Raw_Data!M2="","",VALUE(Raw_Data!M2)),"") -> 10.6 | N2: =IFERROR(IF(Raw_Data!N2="","",VALUE(Raw_Data!N2)),"") -> 12.5 | O2: =IFERROR(IF(AND(N2<>"",M2<>""),N2-M2,""),"") -> 1.9 | P2: =TRIM(CLEAN(Raw_Data!P2)) -> Waiting for client feedback
A3: =TRIM(CLEAN(Raw_Data!A3)) -> TSK-0002 | B3: =TRIM(CLEAN(Raw_Data!B3)) -> Product Launch | C3: =IFERROR(VLOOKUP(TRIM(CLEAN(Raw_Data!C3)),Lookup_Lists!$G:$H,2,FALSE()),TRIM(CLEAN(Raw_Data!C3))) -> Sales | D3: =TRIM(CLEAN(Raw_Data!D3)) -> Ananya Das | E3: =IFERROR(VLOOKUP(TRIM(CLEAN(Raw_Data!E3)),Lookup_Lists!$M:$N,2,FALSE()),TRIM(CLEAN(Raw_Data!E3))) -> Analyst | F3: =IFERROR(VLOOKUP(TRIM(CLEAN(Raw_Data!F3)),Lookup_Lists!$A:$B,2,FALSE()),TRIM(CLEAN(Raw_Data!F3))) -> Low | G3: =IFERROR(VLOOKUP(TRIM(CLEAN(Raw_Data!G3)),Lookup_Lists!$J:$K,2,FALSE()),TRIM(CLEAN(Raw_Data!G3))) -> Design | H3: =IF(Raw_Data!H3="","",Raw_Data!H3) -> 45662 | I3: =IF(Raw_Data!I3="","",Raw_Data!I3) -> 45708 | J3: =IF(Raw_Data!J3="","",Raw_Data!J3) | K3: =IFERROR(VLOOKUP(TRIM(CLEAN(Raw_Data!K3)),Lookup_Lists!$D:$E,2,FALSE()),TRIM(CLEAN(Raw_Data!K3))) -> On Hold | L3: =IF(TRIM(CLEAN(Raw_Data!L3))="","",IFERROR(MIN(100,MAX(0,VALUE(SUBSTITUTE(TRIM(CLEAN(Raw_Data!L3)),"%",""))))/100,0)) | M3: =IFERROR(IF(Raw_Data!M3="","",VALUE(Raw_Data!M3)),"") -> 48.8 | N3: =IFERROR(IF(Raw_Data!N3="","",VALUE(Raw_Data!N3)),"") | O3: =IFERROR(IF(AND(N3<>"",M3<>""),N3-M3,""),"") | P3: =TRIM(CLEAN(Raw_Data!P3))
A4: =TRIM(CLEAN(Raw_Data!A4)) -> TSK-0003 | B4: =TRIM(CLEAN(Raw_Data!B4)) -> Marketing Campaign | C4: =IFERROR(VLOOKUP(TRIM(CLEAN(Raw_Data!C4)),Lookup_Lists!$G:$H,2,FALSE()),TRIM(CLEAN(Raw_Data!C4))) -> HR | D4: =TRIM(CLEAN(Raw_Data!D4)) -> Vikram Singh | E4: =IFERROR(VLOOKUP(TRIM(CLEAN(Raw_Data!E4)),Lookup_Lists!$M:$N,2,FALSE()),TRIM(CLEAN(Raw_Data!E4))) -> Developer | F4: =IFERROR(VLOOKUP(TRIM(CLEAN(Raw_Data!F4)),Lookup_Lists!$A:$B,2,FALSE()),TRIM(CLEAN(Raw_Data!F4))) -> High | G4: =IFERROR(VLOOKUP(TRIM(CLEAN(Raw_Data!G4)),Lookup_Lists!$J:$K,2,FALSE()),TRIM(CLEAN(Raw_Data!G4))) -> Planning | H4: =IF(Raw_Data!H4="","",Raw_Data!H4) -> 45348 | I4: =IF(Raw_Data!I4="","",Raw_Data!I4) -> 45358 | J4: =IF(Raw_Data!J4="","",Raw_Data!J4) | K4: =IFERROR(VLOOKUP(TRIM(CLEAN(Raw_Data!K4)),Lookup_Lists!$D:$E,2,FALSE()),TRIM(CLEAN(Raw_Data!K4))) -> On Hold | L4: =IF(TRIM(CLEAN(Raw_Data!L4))="","",IFERROR(MIN(100,MAX(0,VALUE(SUBSTITUTE(TRIM(CLEAN(Raw_Data!L4)),"%",""))))/100,0)) | M4: =IFERROR(IF(Raw_Data!M4="","",VALUE(Raw_Data!M4)),"") -> 68.4 | N4: =IFERROR(IF(Raw_Data!N4="","",VALUE(Raw_Data!N4)),"") | O4: =IFERROR(IF(AND(N4<>"",M4<>""),N4-M4,""),"") | P4: =TRIM(CLEAN(Raw_Data!P4)) -> Resource conflict
A5: =TRIM(CLEAN(Raw_Data!A5)) -> TSK-0004 | B5: =TRIM(CLEAN(Raw_Data!B5)) -> Data Analytics Platform | C5: =IFERROR(VLOOKUP(TRIM(CLEAN(Raw_Data!C5)),Lookup_Lists!$G:$H,2,FALSE()),TRIM(CLEAN(Raw_Data!C5))) -> Finance | D5: =TRIM(CLEAN(Raw_Data!D5)) -> Karan Malhotra | E5: =IFERROR(VLOOKUP(TRIM(CLEAN(Raw_Data!E5)),Lookup_Lists!$M:$N,2,FALSE()),TRIM(CLEAN(Raw_Data!E5))) -> Tester | F5: =IFERROR(VLOOKUP(TRIM(CLEAN(Raw_Data!F5)),Lookup_Lists!$A:$B,2,FALSE()),TRIM(CLEAN(Raw_Data!F5))) -> High | G5: =IFERROR(VLOOKUP(TRIM(CLEAN(Raw_Data!G5)),Lookup_Lists!$J:$K,2,FALSE()),TRIM(CLEAN(Raw_Data!G5))) -> Planning | H5: =IF(Raw_Data!H5="","",Raw_Data!H5) -> 45617 | I5: =IF(Raw_Data!I5="","",Raw_Data!I5) -> 45661 | J5: =IF(Raw_Data!J5="","",Raw_Data!J5) | K5: =IFERROR(VLOOKUP(TRIM(CLEAN(Raw_Data!K5)),Lookup_Lists!$D:$E,2,FALSE()),TRIM(CLEAN(Raw_Data!K5))) -> Not Started | L5: =IF(TRIM(CLEAN(Raw_Data!L5))="","",IFERROR(MIN(100,MAX(0,VALUE(SUBSTITUTE(TRIM(CLEAN(Raw_Data!L5)),"%",""))))/100,0)) | M5: =IFERROR(IF(Raw_Data!M5="","",VALUE(Raw_Data!M5)),"") -> 18.6 | N5: =IFERROR(IF(Raw_Data!N5="","",VALUE(Raw_Data!N5)),"") | O5: =IFERROR(IF(AND(N5<>"",M5<>""),N5-M5,""),"") | P5: =TRIM(CLEAN(Raw_Data!P5)) -> Need more resources
A6: =TRIM(CLEAN(Raw_Data!A6)) -> TSK-0005 | B6: =TRIM(CLEAN(Raw_Data!B6)) -> Employee Onboarding | C6: =IFERROR(VLOOKUP(TRIM(CLEAN(Raw_Data!C6)),Lookup_Lists!$G:$H,2,FALSE()),TRIM(CLEAN(Raw_Data!C6))) -> IT | D6: =TRIM(CLEAN(Raw_Data!D6)) -> Meera Thakur | E6: =IFERROR(VLOOKUP(TRIM(CLEAN(Raw_Data!E6)),Lookup_Lists!$M:$N,2,FALSE()),TRIM(CLEAN(Raw_Data!E6))) -> Manager | F6: =IFERROR(VLOOKUP(TRIM(CLEAN(Raw_Data!F6)),Lookup_Lists!$A:$B,2,FALSE()),TRIM(CLEAN(Raw_Data!F6))) -> Critical | G6: =IFERROR(VLOOKUP(TRIM(CLEAN(Raw_Data!G6)),Lookup_Lists!$J:$K,2,FALSE()),TRIM(CLEAN(Raw_Data!G6))) -> Testing | H6: =IF(Raw_Data!H6="","",Raw_Data!H6) -> 45490 | I6: =IF(Raw_Data!I6="","",Raw_Data!I6) -> 45512 | J6: =IF(Raw_Data!J6="","",Raw_Data!J6) | K6: =IFERROR(VLOOKUP(TRIM(CLEAN(Raw_Data!K6)),Lookup_Lists!$D:$E,2,FALSE()),TRIM(CLEAN(Raw_Data!K6))) -> On Hold | L6: =IF(TRIM(CLEAN(Raw_Data!L6))="","",IFERROR(MIN(100,MAX(0,VALUE(SUBSTITUTE(TRIM(CLEAN(Raw_Data!L6)),"%",""))))/100,0)) -> 0.28 | M6: =IFERROR(IF(Raw_Data!M6="","",VALUE(Raw_Data!M6)),"") -> 32.1 | N6: =IFERROR(IF(Raw_Data!N6="","",VALUE(Raw_Data!N6)),"") | O6: =IFERROR(IF(AND(N6<>"",M6<>""),N6-M6,""),"") | P6: =TRIM(CLEAN(Raw_Data!P6)) -> final review stage
A7: =TRIM(CLEAN(Raw_Data!A7)) -> TSK-0006 | B7: =TRIM(CLEAN(Raw_Data!B7)) -> CRM Migration | C7: =IFERROR(VLOOKUP(TRIM(CLEAN(Raw_Data!C7)),Lookup_Lists!$G:$H,2,FALSE()),TRIM(CLEAN(Raw_Data!C7))) -> Finance | D7: =TRIM(CLEAN(Raw_Data!D7)) -> Deepak Nair | E7: =IFERROR(VLOOKUP(TRIM(CLEAN(Raw_Data!E7)),Lookup_Lists!$M:$N,2,FALSE()),TRIM(CLEAN(Raw_Data!E7))) -> Manager | F7: =IFERROR(VLOOKUP(TRIM(CLEAN(Raw_Data!F7)),Lookup_Lists!$A:$B,2,FALSE()),TRIM(CLEAN(Raw_Data!F7))) -> High | G7: =IFERROR(VLOOKUP(TRIM(CLEAN(Raw_Data!G7)),Lookup_Lists!$J:$K,2,FALSE()),TRIM(CLEAN(Raw_Data!G7))) -> Documentation | H7: =IF(Raw_Data!H7="","",Raw_Data!H7) -> 45490 | I7: =IF(Raw_Data!I7="","",Raw_Data!I7) -> 45512 | J7: =IF(Raw_Data!J7="","",Raw_Data!J7) | K7: =IFERROR(VLOOKUP(TRIM(CLEAN(Raw_Data!K7)),Lookup_Lists!$D:$E,2,FALSE()),TRIM(CLEAN(Raw_Data!K7))) -> In Progress | L7: =IF(TRIM(CLEAN(Raw_Data!L7))="","",IFERROR(MIN(100,MAX(0,VALUE(SUBSTITUTE(TRIM(CLEAN(Raw_Data!L7)),"%",""))))/100,0)) -> 0.73 | M7: =IFERROR(IF(Raw_Data!M7="","",VALUE(Raw_Data!M7)),"") -> 66.5 | N7: =IFERROR(IF(Raw_Data!N7="","",VALUE(Raw_Data!N7)),"") -> 25.2 | O7: =IFERROR(IF(AND(N7<>"",M7<>""),N7-M7,""),"") -> -41.3 | P7: =TRIM(CLEAN(Raw_Data!P7)) -> On track
A8: =TRIM(CLEAN(Raw_Data!A8)) -> TSK-0007 | B8: =TRIM(CLEAN(Raw_Data!B8)) -> Mobile App v2 | C8: =IFERROR(VLOOKUP(TRIM(CLEAN(Raw_Data!C8)),Lookup_Lists!$G:$H,2,FALSE()),TRIM(CLEAN(Raw_Data!C8))) -> HR | D8: =TRIM(CLEAN(Raw_Data!D8)) -> Sneha Gupta | E8: =IFERROR(VLOOKUP(TRIM(CLEAN(Raw_Data!E8)),Lookup_Lists!$M:$N,2,FALSE()),TRIM(CLEAN(Raw_Data!E8))) -> Lead | F8: =IFERROR(VLOOKUP(TRIM(CLEAN(Raw_Data!F8)),Lookup_Lists!$A:$B,2,FALSE()),TRIM(CLEAN(Raw_Data!F8))) -> Medium | G8: =IFERROR(VLOOKUP(TRIM(CLEAN(Raw_Data!G8)),Lookup_Lists!$J:$K,2,FALSE()),TRIM(CLEAN(Raw_Data!G8))) -> Documentation | H8: =IF(Raw_Data!H8="","",Raw_Data!H8) -> 45369 | I8: =IF(Raw_Data!I8="","",Raw_Data!I8) -> 45390 | J8: =IF(Raw_Data!J8="","",Raw_Data!J8) | K8: =IFERROR(VLOOKUP(TRIM(CLEAN(Raw_Data!K8)),Lookup_Lists!$D:$E,2,FALSE()),TRIM(CLEAN(Raw_Data!K8))) -> In Progress | L8: =IF(TRIM(CLEAN(Raw_Data!L8))="","",IFERROR(MIN(100,MAX(0,VALUE(SUBSTITUTE(TRIM(CLEAN(Raw_Data!L8)),"%",""))))/100,0)) -> 0.65 | M8: =IFERROR(IF(Raw_Data!M8="","",VALUE(Raw_Data!M8)),"") -> 60.8 | N8: =IFERROR(IF(Raw_Data!N8="","",VALUE(Raw_Data!N8)),"") -> 32.8 | O8: =IFERROR(IF(AND(N8<>"",M8<>""),N8-M8,""),"") -> -28 | P8: =TRIM(CLEAN(Raw_Data!P8)) -> Stakeholder review next week
A9: =TRIM(CLEAN(Raw_Data!A9)) -> TSK-0008 | B9: =TRIM(CLEAN(Raw_Data!B9)) -> Annual Audit | C9: =IFERROR(VLOOKUP(TRIM(CLEAN(Raw_Data!C9)),Lookup_Lists!$G:$H,2,FALSE()),TRIM(CLEAN(Raw_Data!C9))) -> Sales | D9: =TRIM(CLEAN(Raw_Data!D9)) -> Kavita Rao | E9: =IFERROR(VLOOKUP(TRIM(CLEAN(Raw_Data!E9)),Lookup_Lists!$M:$N,2,FALSE()),TRIM(CLEAN(Raw_Data!E9))) -> Analyst | F9: =IFERROR(VLOOKUP(TRIM(CLEAN(Raw_Data!F9)),Lookup_Lists!$A:$B,2,FALSE()),TRIM(CLEAN(Raw_Data!F9))) -> Critical | G9: =IFERROR(VLOOKUP(TRIM(CLEAN(Raw_Data!G9)),Lookup_Lists!$J:$K,2,FALSE()),TRIM(CLEAN(Raw_Data!G9))) -> Development | H9: =IF(Raw_Data!H9="","",Raw_Data!H9) -> 45352 | I9: =IF(Raw_Data!I9="","",Raw_Data!I9) -> 45366 | J9: =IF(Raw_Data!J9="","",Raw_Data!J9) | K9: =IFERROR(VLOOKUP(TRIM(CLEAN(Raw_Data!K9)),Lookup_Lists!$D:$E,2,FALSE()),TRIM(CLEAN(Raw_Data!K9))) -> In Progress | L9: =IF(TRIM(CLEAN(Raw_Data!L9))="","",IFERROR(MIN(100,MAX(0,VALUE(SUBSTITUTE(TRIM(CLEAN(Raw_Data!L9)),"%",""))))/100,0)) | M9: =IFERROR(IF(Raw_Data!M9="","",VALUE(Raw_Data!M9)),"") -> 33 | N9: =IFERROR(IF(Raw_Data!N9="","",VALUE(Raw_Data!N9)),"") -> 16.7 | O9: =IFERROR(IF(AND(N9<>"",M9<>""),N9-M9,""),"") -> -16.3 | P9: =TRIM(CLEAN(Raw_Data!P9)) -> Priority shifted
A10: =TRIM(CLEAN(Raw_Data!A10)) -> TSK-0009 | B10: =TRIM(CLEAN(Raw_Data!B10)) -> CRM Migration | C10: =IFERROR(VLOOKUP(TRIM(CLEAN(Raw_Data!C10)),Lookup_Lists!$G:$H,2,FALSE()),TRIM(CLEAN(Raw_Data!C10))) -> HR | D10: =TRIM(CLEAN(Raw_Data!D10)) -> Sanjay Kulkarni | E10: =IFERROR(VLOOKUP(TRIM(CLEAN(Raw_Data!E10)),Lookup_Lists!$M:$N,2,FALSE()),TRIM(CLEAN(Raw_Data!E10))) -> Designer | F10: =IFERROR(VLOOKUP(TRIM(CLEAN(Raw_Data!F10)),Lookup_Lists!$A:$B,2,FALSE()),TRIM(CLEAN(Raw_Data!F10))) -> High | G10: =IFERROR(VLOOKUP(TRIM(CLEAN(Raw_Data!G10)),Lookup_Lists!$J:$K,2,FALSE()),TRIM(CLEAN(Raw_Data!G10))) -> Planning | H10: =IF(Raw_Data!H10="","",Raw_Data!H10) -> 45518 | I10: =IF(Raw_Data!I10="","",Raw_Data!I10) -> 45533 | J10: =IF(Raw_Data!J10="","",Raw_Data!J10) | K10: =IFERROR(VLOOKUP(TRIM(CLEAN(Raw_Data!K10)),Lookup_Lists!$D:$E,2,FALSE()),TRIM(CLEAN(Raw_Data!K10))) -> On Hold | L10: =IF(TRIM(CLEAN(Raw_Data!L10))="","",IFERROR(MIN(100,MAX(0,VALUE(SUBSTITUTE(TRIM(CLEAN(Raw_Data!L10)),"%",""))))/100,0)) | M10: =IFERROR(IF(Raw_Data!M10="","",VALUE(Raw_Data!M10)),"") -> 70.6 | N10: =IFERROR(IF(Raw_Data!N10="","",VALUE(Raw_Data!N10)),"") -> 0 | O10: =IFERROR(IF(AND(N10<>"",M10<>""),N10-M10,""),"") -> -70.6 | P10: =TRIM(CLEAN(Raw_Data!P10)) -> Rescheduled
A11: =TRIM(CLEAN(Raw_Data!A11)) -> TSK-0010 | B11: =TRIM(CLEAN(Raw_Data!B11)) -> Supply Chain Optimization | C11: =IFERROR(VLOOKUP(TRIM(CLEAN(Raw_Data!C11)),Lookup_Lists!$G:$H,2,FALSE()),TRIM(CLEAN(Raw_Data!C11))) -> Finance | D11: =TRIM(CLEAN(Raw_Data!D11)) -> Meera Thakur | E11: =IFERROR(VLOOKUP(TRIM(CLEAN(Raw_Data!E11)),Lookup_Lists!$M:$N,2,FALSE()),TRIM(CLEAN(Raw_Data!E11))) -> Designer | F11: =IFERROR(VLOOKUP(TRIM(CLEAN(Raw_Data!F11)),Lookup_Lists!$A:$B,2,FALSE()),TRIM(CLEAN(Raw_Data!F11))) -> Critical | G11: =IFERROR(VLOOKUP(TRIM(CLEAN(Raw_Data!G11)),Lookup_Lists!$J:$K,2,FALSE()),TRIM(CLEAN(Raw_Data!G11))) -> Deployment | H11: =IF(Raw_Data!H11="","",Raw_Data!H11) -> 45607 | I11: =IF(Raw_Data!I11="","",Raw_Data!I11) -> 45624 | J11: =IF(Raw_Data!J11="","",Raw_Data!J11) | K11: =IFERROR(VLOOKUP(TRIM(CLEAN(Raw_Data!K11)),Lookup_Lists!$D:$E,2,FALSE()),TRIM(CLEAN(Raw_Data!K11))) -> In Progress | L11: =IF(TRIM(CLEAN(Raw_Data!L11))="","",IFERROR(MIN(100,MAX(0,VALUE(SUBSTITUTE(TRIM(CLEAN(Raw_Data!L11)),"%",""))))/100,0)) -> 0.57 | M11: =IFERROR(IF(Raw_Data!M11="","",VALUE(Raw_Data!M11)),"") -> 49.5 | N11: =IFERROR(IF(Raw_Data!N11="","",VALUE(Raw_Data!N11)),"") -> 6.8 | O11: =IFERROR(IF(AND(N11<>"",M11<>""),N11-M11,""),"") -> -42.7 | P11: =TRIM(CLEAN(Raw_Data!P11)) -> Stakeholder review next week
A12: =TRIM(CLEAN(Raw_Data!A12)) -> TSK-0011 | B12: =TRIM(CLEAN(Raw_Data!B12)) -> Product Launch | C12: =IFERROR(VLOOKUP(TRIM(CLEAN(Raw_Data!C12)),Lookup_Lists!$G:$H,2,FALSE()),TRIM(CLEAN(Raw_Data!C12))) -> IT | D12: =TRIM(CLEAN(Raw_Data!D12)) -> Sneha Gupta | E12: =IFERROR(VLOOKUP(TRIM(CLEAN(Raw_Data!E12)),Lookup_Lists!$M:$N,2,FALSE()),TRIM(CLEAN(Raw_Data!E12))) -> Analyst | F12: =IFERROR(VLOOKUP(TRIM(CLEAN(Raw_Data!F12)),Lookup_Lists!$A:$B,2,FALSE()),TRIM(CLEAN(Raw_Data!F12))) -> High | G12: =IFERROR(VLOOKUP(TRIM(CLEAN(Raw_Data!G12)),Lookup_Lists!$J:$K,2,FALSE()),TRIM(CLEAN(Raw_Data!G12))) -> Deployment | H12: =IF(Raw_Data!H12="","",Raw_Data!H12) -> 45331 | I12: =IF(Raw_Data!I12="","",Raw_Data!I12) -> 45384 | J12: =IF(Raw_Data!J12="","",Raw_Data!J12) | K12: =IFERROR(VLOOKUP(TRIM(CLEAN(Raw_Data!K12)),Lookup_Lists!$D:$E,2,FALSE()),TRIM(CLEAN(Raw_Data!K12))) -> In Progress | L12: =IF(TRIM(CLEAN(Raw_Data!L12))="","",IFERROR(MIN(100,MAX(0,VALUE(SUBSTITUTE(TRIM(CLEAN(Raw_Data!L12)),"%",""))))/100,0)) -> 0.62 | M12: =IFERROR(IF(Raw_Data!M12="","",VALUE(Raw_Data!M12)),"") -> 24.1 | N12: =IFERROR(IF(Raw_Data!N12="","",VALUE(Raw_Data!N12)),"") -> 10.3 | O12: =IFERROR(IF(AND(N12<>"",M12<>""),N12-M12,""),"") -> -13.8 | P12: =TRIM(CLEAN(Raw_Data!P12)) -> Almost done
A13: =TRIM(CLEAN(Raw_Data!A13)) -> TSK-0012 | B13: =TRIM(CLEAN(Raw_Data!B13)) -> Product Launch | C13: =IFERROR(VLOOKUP(TRIM(CLEAN(Raw_Data!C13)),Lookup_Lists!$G:$H,2,FALSE()),TRIM(CLEAN(Raw_Data!C13))) -> HR | D13: =TRIM(CLEAN(Raw_Data!D13)) -> Arjun Mehta | E13: =IFERROR(VLOOKUP(TRIM(CLEAN(Raw_Data!E13)),Lookup_Lists!$M:$N,2,FALSE()),TRIM(CLEAN(Raw_Data!E13))) -> Tester | F13: =IFERROR(VLOOKUP(TRIM(CLEAN(Raw_Data!F13)),Lookup_Lists!$A:$B,2,FALSE()),TRIM(CLEAN(Raw_Data!F13))) -> Medium | G13: =IFERROR(VLOOKUP(TRIM(CLEAN(Raw_Data!G13)),Lookup_Lists!$J:$K,2,FALSE()),TRIM(CLEAN(Raw_Data!G13))) -> Deployment | H13: =IF(Raw_Data!H13="","",Raw_Data!H13) -> 45527 | I13: =IF(Raw_Data!I13="","",Raw_Data!I13) -> 45539 | J13: =IF(Raw_Data!J13="","",Raw_Data!J13) | K13: =IFERROR(VLOOKUP(TRIM(CLEAN(Raw_Data!K13)),Lookup_Lists!$D:$E,2,FALSE()),TRIM(CLEAN(Raw_Data!K13))) -> In Progress | L13: =IF(TRIM(CLEAN(Raw_Data!L13))="","",IFERROR(MIN(100,MAX(0,VALUE(SUBSTITUTE(TRIM(CLEAN(Raw_Data!L13)),"%",""))))/100,0)) -> 0.38 | M13: =IFERROR(IF(Raw_Data!M13="","",VALUE(Raw_Data!M13)),"") -> 48.7 | N13: =IFERROR(IF(Raw_Data!N13="","",VALUE(Raw_Data!N13)),"") | O13: =IFERROR(IF(AND(N13<>"",M13<>""),N13-M13,""),"") | P13: =TRIM(CLEAN(Raw_Data!P13)) -> Needs QA sign-off
... A121: =TRIM(CLEAN(Raw_Data!A121)) -> TSK-0120 | B121: =TRIM(CLEAN(Raw_Data!B121)) -> Marketing Campaign | C121: =IFERROR(VLOOKUP(TRIM(CLEAN(Raw_Data!C121)),Lookup_Lists!$G:$H,2,FALSE()),TRIM(CLEAN(Raw_Data!C121))) -> HR | D121: =TRIM(CLEAN(Raw_Data!D121)) -> Amit Verma | E121: =IFERROR(VLOOKUP(TRIM(CLEAN(Raw_Data!E121)),Lookup_Lists!$M:$N,2,FALSE()),TRIM(CLEAN(Raw_Data!E121))) -> Lead | F121: =IFERROR(VLOOKUP(TRIM(CLEAN(Raw_Data!F121)),Lookup_Lists!$A:$B,2,FALSE()),TRIM(CLEAN(Raw_Data!F121))) -> Low | G121: =IFERROR(VLOOKUP(TRIM(CLEAN(Raw_Data!G121)),Lookup_Lists!$J:$K,2,FALSE()),TRIM(CLEAN(Raw_Data!G121))) -> Deployment | H121: =IF(Raw_Data!H121="","",Raw_Data!H121) -> 45484 | I121: =IF(Raw_Data!I121="","",Raw_Data!I121) -> 45540 | J121: =IF(Raw_Data!J121="","",Raw_Data!J121) | K121: =IFERROR(VLOOKUP(TRIM(CLEAN(Raw_Data!K121)),Lookup_Lists!$D:$E,2,FALSE()),TRIM(CLEAN(Raw_Data!K121))) -> Cancelled | L121: =IF(TRIM(CLEAN(Raw_Data!L121))="","",IFERROR(MIN(100,MAX(0,VALUE(SUBSTITUTE(TRIM(CLEAN(Raw_Data!L121)),"%",""))))/100,0)) | M121: =IFERROR(IF(Raw_Data!M121="","",VALUE(Raw_Data!M121)),"") -> 64.9 | N121: =IFERROR(IF(Raw_Data!N121="","",VALUE(Raw_Data!N121)),"") | O121: =IFERROR(IF(AND(N121<>"",M121<>""),N121-M121,""),"") | P121: =TRIM(CLEAN(Raw_Data!P121))

Sheet Calc_Helper
A1: Task ID | B1: Is_Completed | C1: Is_Pending | D1: Is_Delayed | E1: Days_Open | F1: Delay_Days | G1: Cycle_Time_Days | H1: Lead_Time_Days | I1: Due_Month | J1: Start_Month | K1: Completion_Month | L1: Year | M1: Month_Number | N1: Month_Name | O1: Overdue_Flag | P1: High_Priority_Open_Flag | Q1: SLA_Breach_Flag | R1: Stale_In_Progress_Flag | S1: Productivity_Flag | T1: On_Time_Flag | U1: Progress_Valid_Flag
A2: =Clean_Data!A2 -> TSK-0001 | B2: =Clean_Data!K2="Completed" -> TRUE | C2: =OR(Clean_Data!K2="Not Started",Clean_Data!K2="In Progress",Clean_Data!K2="On Hold") -> FALSE | D2: =AND(ISNUMBER(Clean_Data!I2),Clean_Data!I2<TODAY(),Clean_Data!K2<>"Completed",Clean_Data!K2<>"Cancelled") -> FALSE | E2: =IF(AND(ISNUMBER(Clean_Data!H2),Clean_Data!K2<>"Completed",Clean_Data!K2<>"Cancelled"),TODAY()-Clean_Data!H2,"") | F2: =IF(AND(B2=TRUE(),ISNUMBER(Clean_Data!J2),ISNUMBER(Clean_Data!I2)),MAX(0,Clean_Data!J2-Clean_Data!I2),IF(AND(B2=FALSE(),ISNUMBER(Clean_Data!I2),Clean_Data!I2<TODAY(),Clean_Data!K2<>"Cancelled"),MAX(0,TODAY()-Clean_Data!I2),"")) -> 11 | G2: =IF(AND(B2=TRUE(),ISNUMBER(Clean_Data!J2),ISNUMBER(Clean_Data!H2)),Clean_Data!J2-Clean_Data!H2,"") -> 63 | H2: =IF(AND(ISNUMBER(Clean_Data!J2),ISNUMBER(Clean_Data!H2)),Clean_Data!J2-Clean_Data!H2,IF(ISNUMBER(Clean_Data!H2),TODAY()-Clean_Data!H2,"")) -> 63 | I2: =IF(ISNUMBER(Clean_Data!I2),TEXT(Clean_Data!I2,"YYYY-MM"),"") -> 2024-05 | J2: =IF(ISNUMBER(Clean_Data!H2),TEXT(Clean_Data!H2,"YYYY-MM"),"") -> 2024-03 | K2: =IF(ISNUMBER(Clean_Data!J2),TEXT(Clean_Data!J2,"YYYY-MM"),"") -> 2024-05 | L2: =IF(ISNUMBER(Clean_Data!H2),YEAR(Clean_Data!H2),"") -> 2024 | M2: =IF(ISNUMBER(Clean_Data!H2),MONTH(Clean_Data!H2),"") -> 3 | N2: =IF(ISNUMBER(Clean_Data!H2),TEXT(Clean_Data!H2,"MMMM"),"") -> March | O2: =D2 -> FALSE | P2: =AND(OR(Clean_Data!F2="High",Clean_Data!F2="Critical"),C2=TRUE()) -> FALSE | Q2: =AND(OR(Clean_Data!F2="High",Clean_Data!F2="Critical"),D2=TRUE()) -> FALSE | R2: =AND(Clean_Data!K2="In Progress",ISNUMBER(Clean_Data!H2),TODAY()-Clean_Data!H2>30) -> FALSE | S2: =IF(B2=TRUE(),IF(AND(ISNUMBER(Clean_Data!N2),ISNUMBER(Clean_Data!M2),Clean_Data!M2>0),IF(Clean_Data!N2<=Clean_Data!M2*1.2,"Healthy","Over Budget"),"N/A"),IF(AND(Clean_Data!K2="In Progress",ISNUMBER(Clean_Data!L2)),IF(Clean_Data!L2>=0.5,"On Track","Slow"),"N/A")) -> Healthy | T2: =IF(AND(B2=TRUE(),ISNUMBER(Clean_Data!J2),ISNUMBER(Clean_Data!I2)),Clean_Data!J2<=Clean_Data!I2,"") -> FALSE | U2: =IF(NOT(ISNUMBER(Clean_Data!L2)),FALSE(),AND(Clean_Data!L2>=0,Clean_Data!L2<=1)) -> TRUE
A3: =Clean_Data!A3 -> TSK-0002 | B3: =Clean_Data!K3="Completed" -> FALSE | C3: =OR(Clean_Data!K3="Not Started",Clean_Data!K3="In Progress",Clean_Data!K3="On Hold") -> TRUE | D3: =AND(ISNUMBER(Clean_Data!I3),Clean_Data!I3<TODAY(),Clean_Data!K3<>"Completed",Clean_Data!K3<>"Cancelled") -> TRUE | E3: =IF(AND(ISNUMBER(Clean_Data!H3),Clean_Data!K3<>"Completed",Clean_Data!K3<>"Cancelled"),TODAY()-Clean_Data!H3,"") -> 464 | F3: =IF(AND(B3=TRUE(),ISNUMBER(Clean_Data!J3),ISNUMBER(Clean_Data!I3)),MAX(0,Clean_Data!J3-Clean_Data!I3),IF(AND(B3=FALSE(),ISNUMBER(Clean_Data!I3),Clean_Data!I3<TODAY(),Clean_Data!K3<>"Cancelled"),MAX(0,TODAY()-Clean_Data!I3),"")) -> 418 | G3: =IF(AND(B3=TRUE(),ISNUMBER(Clean_Data!J3),ISNUMBER(Clean_Data!H3)),Clean_Data!J3-Clean_Data!H3,"") | H3: =IF(AND(ISNUMBER(Clean_Data!J3),ISNUMBER(Clean_Data!H3)),Clean_Data!J3-Clean_Data!H3,IF(ISNUMBER(Clean_Data!H3),TODAY()-Clean_Data!H3,"")) -> 464 | I3: =IF(ISNUMBER(Clean_Data!I3),TEXT(Clean_Data!I3,"YYYY-MM"),"") -> 2025-02 | J3: =IF(ISNUMBER(Clean_Data!H3),TEXT(Clean_Data!H3,"YYYY-MM"),"") -> 2025-01 | K3: =IF(ISNUMBER(Clean_Data!J3),TEXT(Clean_Data!J3,"YYYY-MM"),"") | L3: =IF(ISNUMBER(Clean_Data!H3),YEAR(Clean_Data!H3),"") -> 2025 | M3: =IF(ISNUMBER(Clean_Data!H3),MONTH(Clean_Data!H3),"") -> 1 | N3: =IF(ISNUMBER(Clean_Data!H3),TEXT(Clean_Data!H3,"MMMM"),"") -> January | O3: =D3 -> TRUE | P3: =AND(OR(Clean_Data!F3="High",Clean_Data!F3="Critical"),C3=TRUE()) -> FALSE | Q3: =AND(OR(Clean_Data!F3="High",Clean_Data!F3="Critical"),D3=TRUE()) -> FALSE | R3: =AND(Clean_Data!K3="In Progress",ISNUMBER(Clean_Data!H3),TODAY()-Clean_Data!H3>30) -> FALSE | S3: =IF(B3=TRUE(),IF(AND(ISNUMBER(Clean_Data!N3),ISNUMBER(Clean_Data!M3),Clean_Data!M3>0),IF(Clean_Data!N3<=Clean_Data!M3*1.2,"Healthy","Over Budget"),"N/A"),IF(AND(Clean_Data!K3="In Progress",ISNUMBER(Clean_Data!L3)),IF(Clean_Data!L3>=0.5,"On Track","Slow"),"N/A")) -> N/A | T3: =IF(AND(B3=TRUE(),ISNUMBER(Clean_Data!J3),ISNUMBER(Clean_Data!I3)),Clean_Data!J3<=Clean_Data!I3,"") | U3: =IF(NOT(ISNUMBER(Clean_Data!L3)),FALSE(),AND(Clean_Data!L3>=0,Clean_Data!L3<=1)) -> FALSE
A4: =Clean_Data!A4 -> TSK-0003 | B4: =Clean_Data!K4="Completed" -> FALSE | C4: =OR(Clean_Data!K4="Not Started",Clean_Data!K4="In Progress",Clean_Data!K4="On Hold") -> TRUE | D4: =AND(ISNUMBER(Clean_Data!I4),Clean_Data!I4<TODAY(),Clean_Data!K4<>"Completed",Clean_Data!K4<>"Cancelled") -> TRUE | E4: =IF(AND(ISNUMBER(Clean_Data!H4),Clean_Data!K4<>"Completed",Clean_Data!K4<>"Cancelled"),TODAY()-Clean_Data!H4,"") -> 778 | F4: =IF(AND(B4=TRUE(),ISNUMBER(Clean_Data!J4),ISNUMBER(Clean_Data!I4)),MAX(0,Clean_Data!J4-Clean_Data!I4),IF(AND(B4=FALSE(),ISNUMBER(Clean_Data!I4),Clean_Data!I4<TODAY(),Clean_Data!K4<>"Cancelled"),MAX(0,TODAY()-Clean_Data!I4),"")) -> 768 | G4: =IF(AND(B4=TRUE(),ISNUMBER(Clean_Data!J4),ISNUMBER(Clean_Data!H4)),Clean_Data!J4-Clean_Data!H4,"") | H4: =IF(AND(ISNUMBER(Clean_Data!J4),ISNUMBER(Clean_Data!H4)),Clean_Data!J4-Clean_Data!H4,IF(ISNUMBER(Clean_Data!H4),TODAY()-Clean_Data!H4,"")) -> 778 | I4: =IF(ISNUMBER(Clean_Data!I4),TEXT(Clean_Data!I4,"YYYY-MM"),"") -> 2024-03 | J4: =IF(ISNUMBER(Clean_Data!H4),TEXT(Clean_Data!H4,"YYYY-MM"),"") -> 2024-02 | K4: =IF(ISNUMBER(Clean_Data!J4),TEXT(Clean_Data!J4,"YYYY-MM"),"") | L4: =IF(ISNUMBER(Clean_Data!H4),YEAR(Clean_Data!H4),"") -> 2024 | M4: =IF(ISNUMBER(Clean_Data!H4),MONTH(Clean_Data!H4),"") -> 2 | N4: =IF(ISNUMBER(Clean_Data!H4),TEXT(Clean_Data!H4,"MMMM"),"") -> February | O4: =D4 -> TRUE | P4: =AND(OR(Clean_Data!F4="High",Clean_Data!F4="Critical"),C4=TRUE()) -> TRUE | Q4: =AND(OR(Clean_Data!F4="High",Clean_Data!F4="Critical"),D4=TRUE()) -> TRUE | R4: =AND(Clean_Data!K4="In Progress",ISNUMBER(Clean_Data!H4),TODAY()-Clean_Data!H4>30) -> FALSE | S4: =IF(B4=TRUE(),IF(AND(ISNUMBER(Clean_Data!N4),ISNUMBER(Clean_Data!M4),Clean_Data!M4>0),IF(Clean_Data!N4<=Clean_Data!M4*1.2,"Healthy","Over Budget"),"N/A"),IF(AND(Clean_Data!K4="In Progress",ISNUMBER(Clean_Data!L4)),IF(Clean_Data!L4>=0.5,"On Track","Slow"),"N/A")) -> N/A | T4: =IF(AND(B4=TRUE(),ISNUMBER(Clean_Data!J4),ISNUMBER(Clean_Data!I4)),Clean_Data!J4<=Clean_Data!I4,"") | U4: =IF(NOT(ISNUMBER(Clean_Data!L4)),FALSE(),AND(Clean_Data!L4>=0,Clean_Data!L4<=1)) -> FALSE
A5: =Clean_Data!A5 -> TSK-0004 | B5: =Clean_Data!K5="Completed" -> FALSE | C5: =OR(Clean_Data!K5="Not Started",Clean_Data!K5="In Progress",Clean_Data!K5="On Hold") -> TRUE | D5: =AND(ISNUMBER(Clean_Data!I5),Clean_Data!I5<TODAY(),Clean_Data!K5<>"Completed",Clean_Data!K5<>"Cancelled") -> TRUE | E5: =IF(AND(ISNUMBER(Clean_Data!H5),Clean_Data!K5<>"Completed",Clean_Data!K5<>"Cancelled"),TODAY()-Clean_Data!H5,"") -> 509 | F5: =IF(AND(B5=TRUE(),ISNUMBER(Clean_Data!J5),ISNUMBER(Clean_Data!I5)),MAX(0,Clean_Data!J5-Clean_Data!I5),IF(AND(B5=FALSE(),ISNUMBER(Clean_Data!I5),Clean_Data!I5<TODAY(),Clean_Data!K5<>"Cancelled"),MAX(0,TODAY()-Clean_Data!I5),"")) -> 465 | G5: =IF(AND(B5=TRUE(),ISNUMBER(Clean_Data!J5),ISNUMBER(Clean_Data!H5)),Clean_Data!J5-Clean_Data!H5,"") | H5: =IF(AND(ISNUMBER(Clean_Data!J5),ISNUMBER(Clean_Data!H5)),Clean_Data!J5-Clean_Data!H5,IF(ISNUMBER(Clean_Data!H5),TODAY()-Clean_Data!H5,"")) -> 509 | I5: =IF(ISNUMBER(Clean_Data!I5),TEXT(Clean_Data!I5,"YYYY-MM"),"") -> 2025-01 | J5: =IF(ISNUMBER(Clean_Data!H5),TEXT(Clean_Data!H5,"YYYY-MM"),"") -> 2024-11 | K5: =IF(ISNUMBER(Clean_Data!J5),TEXT(Clean_Data!J5,"YYYY-MM"),"") | L5: =IF(ISNUMBER(Clean_Data!H5),YEAR(Clean_Data!H5),"") -> 2024 | M5: =IF(ISNUMBER(Clean_Data!H5),MONTH(Clean_Data!H5),"") -> 11 | N5: =IF(ISNUMBER(Clean_Data!H5),TEXT(Clean_Data!H5,"MMMM"),"") -> November | O5: =D5 -> TRUE | P5: =AND(OR(Clean_Data!F5="High",Clean_Data!F5="Critical"),C5=TRUE()) -> TRUE | Q5: =AND(OR(Clean_Data!F5="High",Clean_Data!F5="Critical"),D5=TRUE()) -> TRUE | R5: =AND(Clean_Data!K5="In Progress",ISNUMBER(Clean_Data!H5),TODAY()-Clean_Data!H5>30) -> FALSE | S5: =IF(B5=TRUE(),IF(AND(ISNUMBER(Clean_Data!N5),ISNUMBER(Clean_Data!M5),Clean_Data!M5>0),IF(Clean_Data!N5<=Clean_Data!M5*1.2,"Healthy","Over Budget"),"N/A"),IF(AND(Clean_Data!K5="In Progress",ISNUMBER(Clean_Data!L5)),IF(Clean_Data!L5>=0.5,"On Track","Slow"),"N/A")) -> N/A | T5: =IF(AND(B5=TRUE(),ISNUMBER(Clean_Data!J5),ISNUMBER(Clean_Data!I5)),Clean_Data!J5<=Clean_Data!I5,"") | U5: =IF(NOT(ISNUMBER(Clean_Data!L5)),FALSE(),AND(Clean_Data!L5>=0,Clean_Data!L5<=1)) -> FALSE
A6: =Clean_Data!A6 -> TSK-0005 | B6: =Clean_Data!K6="Completed" -> FALSE | C6: =OR(Clean_Data!K6="Not Started",Clean_Data!K6="In Progress",Clean_Data!K6="On Hold") -> TRUE | D6: =AND(ISNUMBER(Clean_Data!I6),Clean_Data!I6<TODAY(),Clean_Data!K6<>"Completed",Clean_Data!K6<>"Cancelled") -> TRUE | E6: =IF(AND(ISNUMBER(Clean_Data!H6),Clean_Data!K6<>"Completed",Clean_Data!K6<>"Cancelled"),TODAY()-Clean_Data!H6,"") -> 636 | F6: =IF(AND(B6=TRUE(),ISNUMBER(Clean_Data!J6),ISNUMBER(Clean_Data!I6)),MAX(0,Clean_Data!J6-Clean_Data!I6),IF(AND(B6=FALSE(),ISNUMBER(Clean_Data!I6),Clean_Data!I6<TODAY(),Clean_Data!K6<>"Cancelled"),MAX(0,TODAY()-Clean_Data!I6),"")) -> 614 | G6: =IF(AND(B6=TRUE(),ISNUMBER(Clean_Data!J6),ISNUMBER(Clean_Data!H6)),Clean_Data!J6-Clean_Data!H6,"") | H6: =IF(AND(ISNUMBER(Clean_Data!J6),ISNUMBER(Clean_Data!H6)),Clean_Data!J6-Clean_Data!H6,IF(ISNUMBER(Clean_Data!H6),TODAY()-Clean_Data!H6,"")) -> 636 | I6: =IF(ISNUMBER(Clean_Data!I6),TEXT(Clean_Data!I6,"YYYY-MM"),"") -> 2024-08 | J6: =IF(ISNUMBER(Clean_Data!H6),TEXT(Clean_Data!H6,"YYYY-MM"),"") -> 2024-07 | K6: =IF(ISNUMBER(Clean_Data!J6),TEXT(Clean_Data!J6,"YYYY-MM"),"") | L6: =IF(ISNUMBER(Clean_Data!H6),YEAR(Clean_Data!H6),"") -> 2024 | M6: =IF(ISNUMBER(Clean_Data!H6),MONTH(Clean_Data!H6),"") -> 7 | N6: =IF(ISNUMBER(Clean_Data!H6),TEXT(Clean_Data!H6,"MMMM"),"") -> July | O6: =D6 -> TRUE | P6: =AND(OR(Clean_Data!F6="High",Clean_Data!F6="Critical"),C6=TRUE()) -> TRUE | Q6: =AND(OR(Clean_Data!F6="High",Clean_Data!F6="Critical"),D6=TRUE()) -> TRUE | R6: =AND(Clean_Data!K6="In Progress",ISNUMBER(Clean_Data!H6),TODAY()-Clean_Data!H6>30) -> FALSE | S6: =IF(B6=TRUE(),IF(AND(ISNUMBER(Clean_Data!N6),ISNUMBER(Clean_Data!M6),Clean_Data!M6>0),IF(Clean_Data!N6<=Clean_Data!M6*1.2,"Healthy","Over Budget"),"N/A"),IF(AND(Clean_Data!K6="In Progress",ISNUMBER(Clean_Data!L6)),IF(Clean_Data!L6>=0.5,"On Track","Slow"),"N/A")) -> N/A | T6: =IF(AND(B6=TRUE(),ISNUMBER(Clean_Data!J6),ISNUMBER(Clean_Data!I6)),Clean_Data!J6<=Clean_Data!I6,"") | U6: =IF(NOT(ISNUMBER(Clean_Data!L6)),FALSE(),AND(Clean_Data!L6>=0,Clean_Data!L6<=1)) -> TRUE
A7: =Clean_Data!A7 -> TSK-0006 | B7: =Clean_Data!K7="Completed" -> FALSE | C7: =OR(Clean_Data!K7="Not Started",Clean_Data!K7="In Progress",Clean_Data!K7="On Hold") -> TRUE | D7: =AND(ISNUMBER(Clean_Data!I7),Clean_Data!I7<TODAY(),Clean_Data!K7<>"Completed",Clean_Data!K7<>"Cancelled") -> TRUE | E7: =IF(AND(ISNUMBER(Clean_Data!H7),Clean_Data!K7<>"Completed",Clean_Data!K7<>"Cancelled"),TODAY()-Clean_Data!H7,"") -> 636 | F7: =IF(AND(B7=TRUE(),ISNUMBER(Clean_Data!J7),ISNUMBER(Clean_Data!I7)),MAX(0,Clean_Data!J7-Clean_Data!I7),IF(AND(B7=FALSE(),ISNUMBER(Clean_Data!I7),Clean_Data!I7<TODAY(),Clean_Data!K7<>"Cancelled"),MAX(0,TODAY()-Clean_Data!I7),"")) -> 614 | G7: =IF(AND(B7=TRUE(),ISNUMBER(Clean_Data!J7),ISNUMBER(Clean_Data!H7)),Clean_Data!J7-Clean_Data!H7,"") | H7: =IF(AND(ISNUMBER(Clean_Data!J7),ISNUMBER(Clean_Data!H7)),Clean_Data!J7-Clean_Data!H7,IF(ISNUMBER(Clean_Data!H7),TODAY()-Clean_Data!H7,"")) -> 636 | I7: =IF(ISNUMBER(Clean_Data!I7),TEXT(Clean_Data!I7,"YYYY-MM"),"") -> 2024-08 | J7: =IF(ISNUMBER(Clean_Data!H7),TEXT(Clean_Data!H7,"YYYY-MM"),"") -> 2024-07 | K7: =IF(ISNUMBER(Clean_Data!J7),TEXT(Clean_Data!J7,"YYYY-MM"),"") | L7: =IF(ISNUMBER(Clean_Data!H7),YEAR(Clean_Data!H7),"") -> 2024 | M7: =IF(ISNUMBER(Clean_Data!H7),MONTH(Clean_Data!H7),"") -> 7 | N7: =IF(ISNUMBER(Clean_Data!H7),TEXT(Clean_Data!H7,"MMMM"),"") -> July | O7: =D7 -> TRUE | P7: =AND(OR(Clean_Data!F7="High",Clean_Data!F7="Critical"),C7=TRUE()) -> TRUE | Q7: =AND(OR(Clean_Data!F7="High",Clean_Data!F7="Critical"),D7=TRUE()) -> TRUE | R7: =AND(Clean_Data!K7="In Progress",ISNUMBER(Clean_Data!H7),TODAY()-Clean_Data!H7>30) -> TRUE | S7: =IF(B7=TRUE(),IF(AND(ISNUMBER(Clean_Data!N7),ISNUMBER(Clean_Data!M7),Clean_Data!M7>0),IF(Clean_Data!N7<=Clean_Data!M7*1.2,"Healthy","Over Budget"),"N/A"),IF(AND(Clean_Data!K7="In Progress",ISNUMBER(Clean_Data!L7)),IF(Clean_Data!L7>=0.5,"On Track","Slow"),"N/A")) -> On Track | T7: =IF(AND(B7=TRUE(),ISNUMBER(Clean_Data!J7),ISNUMBER(Clean_Data!I7)),Clean_Data!J7<=Clean_Data!I7,"") | U7: =IF(NOT(ISNUMBER(Clean_Data!L7)),FALSE(),AND(Clean_Data!L7>=0,Clean_Data!L7<=1)) -> TRUE
A8: =Clean_Data!A8 -> TSK-0007 | B8: =Clean_Data!K8="Completed" -> FALSE | C8: =OR(Clean_Data!K8="Not Started",Clean_Data!K8="In Progress",Clean_Data!K8="On Hold") -> TRUE | D8: =AND(ISNUMBER(Clean_Data!I8),Clean_Data!I8<TODAY(),Clean_Data!K8<>"Completed",Clean_Data!K8<>"Cancelled") -> TRUE | E8: =IF(AND(ISNUMBER(Clean_Data!H8),Clean_Data!K8<>"Completed",Clean_Data!K8<>"Cancelled"),TODAY()-Clean_Data!H8,"") -> 757 | F8: =IF(AND(B8=TRUE(),ISNUMBER(Clean_Data!J8),ISNUMBER(Clean_Data!I8)),MAX(0,Clean_Data!J8-Clean_Data!I8),IF(AND(B8=FALSE(),ISNUMBER(Clean_Data!I8),Clean_Data!I8<TODAY(),Clean_Data!K8<>"Cancelled"),MAX(0,TODAY()-Clean_Data!I8),"")) -> 736 | G8: =IF(AND(B8=TRUE(),ISNUMBER(Clean_Data!J8),ISNUMBER(Clean_Data!H8)),Clean_Data!J8-Clean_Data!H8,"") | H8: =IF(AND(ISNUMBER(Clean_Data!J8),ISNUMBER(Clean_Data!H8)),Clean_Data!J8-Clean_Data!H8,IF(ISNUMBER(Clean_Data!H8),TODAY()-Clean_Data!H8,"")) -> 757 | I8: =IF(ISNUMBER(Clean_Data!I8),TEXT(Clean_Data!I8,"YYYY-MM"),"") -> 2024-04 | J8: =IF(ISNUMBER(Clean_Data!H8),TEXT(Clean_Data!H8,"YYYY-MM"),"") -> 2024-03 | K8: =IF(ISNUMBER(Clean_Data!J8),TEXT(Clean_Data!J8,"YYYY-MM"),"") | L8: =IF(ISNUMBER(Clean_Data!H8),YEAR(Clean_Data!H8),"") -> 2024 | M8: =IF(ISNUMBER(Clean_Data!H8),MONTH(Clean_Data!H8),"") -> 3 | N8: =IF(ISNUMBER(Clean_Data!H8),TEXT(Clean_Data!H8,"MMMM"),"") -> March | O8: =D8 -> TRUE | P8: =AND(OR(Clean_Data!F8="High",Clean_Data!F8="Critical"),C8=TRUE()) -> FALSE | Q8: =AND(OR(Clean_Data!F8="High",Clean_Data!F8="Critical"),D8=TRUE()) -> FALSE | R8: =AND(Clean_Data!K8="In Progress",ISNUMBER(Clean_Data!H8),TODAY()-Clean_Data!H8>30) -> TRUE | S8: =IF(B8=TRUE(),IF(AND(ISNUMBER(Clean_Data!N8),ISNUMBER(Clean_Data!M8),Clean_Data!M8>0),IF(Clean_Data!N8<=Clean_Data!M8*1.2,"Healthy","Over Budget"),"N/A"),IF(AND(Clean_Data!K8="In Progress",ISNUMBER(Clean_Data!L8)),IF(Clean_Data!L8>=0.5,"On Track","Slow"),"N/A")) -> On Track | T8: =IF(AND(B8=TRUE(),ISNUMBER(Clean_Data!J8),ISNUMBER(Clean_Data!I8)),Clean_Data!J8<=Clean_Data!I8,"") | U8: =IF(NOT(ISNUMBER(Clean_Data!L8)),FALSE(),AND(Clean_Data!L8>=0,Clean_Data!L8<=1)) -> TRUE
A9: =Clean_Data!A9 -> TSK-0008 | B9: =Clean_Data!K9="Completed" -> FALSE | C9: =OR(Clean_Data!K9="Not Started",Clean_Data!K9="In Progress",Clean_Data!K9="On Hold") -> TRUE | D9: =AND(ISNUMBER(Clean_Data!I9),Clean_Data!I9<TODAY(),Clean_Data!K9<>"Completed",Clean_Data!K9<>"Cancelled") -> TRUE | E9: =IF(AND(ISNUMBER(Clean_Data!H9),Clean_Data!K9<>"Completed",Clean_Data!K9<>"Cancelled"),TODAY()-Clean_Data!H9,"") -> 774 | F9: =IF(AND(B9=TRUE(),ISNUMBER(Clean_Data!J9),ISNUMBER(Clean_Data!I9)),MAX(0,Clean_Data!J9-Clean_Data!I9),IF(AND(B9=FALSE(),ISNUMBER(Clean_Data!I9),Clean_Data!I9<TODAY(),Clean_Data!K9<>"Cancelled"),MAX(0,TODAY()-Clean_Data!I9),"")) -> 760 | G9: =IF(AND(B9=TRUE(),ISNUMBER(Clean_Data!J9),ISNUMBER(Clean_Data!H9)),Clean_Data!J9-Clean_Data!H9,"") | H9: =IF(AND(ISNUMBER(Clean_Data!J9),ISNUMBER(Clean_Data!H9)),Clean_Data!J9-Clean_Data!H9,IF(ISNUMBER(Clean_Data!H9),TODAY()-Clean_Data!H9,"")) -> 774 | I9: =IF(ISNUMBER(Clean_Data!I9),TEXT(Clean_Data!I9,"YYYY-MM"),"") -> 2024-03 | J9: =IF(ISNUMBER(Clean_Data!H9),TEXT(Clean_Data!H9,"YYYY-MM"),"") -> 2024-03 | K9: =IF(ISNUMBER(Clean_Data!J9),TEXT(Clean_Data!J9,"YYYY-MM"),"") | L9: =IF(ISNUMBER(Clean_Data!H9),YEAR(Clean_Data!H9),"") -> 2024 | M9: =IF(ISNUMBER(Clean_Data!H9),MONTH(Clean_Data!H9),"") -> 3 | N9: =IF(ISNUMBER(Clean_Data!H9),TEXT(Clean_Data!H9,"MMMM"),"") -> March | O9: =D9 -> TRUE | P9: =AND(OR(Clean_Data!F9="High",Clean_Data!F9="Critical"),C9=TRUE()) -> TRUE | Q9: =AND(OR(Clean_Data!F9="High",Clean_Data!F9="Critical"),D9=TRUE()) -> TRUE | R9: =AND(Clean_Data!K9="In Progress",ISNUMBER(Clean_Data!H9),TODAY()-Clean_Data!H9>30) -> TRUE | S9: =IF(B9=TRUE(),IF(AND(ISNUMBER(Clean_Data!N9),ISNUMBER(Clean_Data!M9),Clean_Data!M9>0),IF(Clean_Data!N9<=Clean_Data!M9*1.2,"Healthy","Over Budget"),"N/A"),IF(AND(Clean_Data!K9="In Progress",ISNUMBER(Clean_Data!L9)),IF(Clean_Data!L9>=0.5,"On Track","Slow"),"N/A")) -> N/A | T9: =IF(AND(B9=TRUE(),ISNUMBER(Clean_Data!J9),ISNUMBER(Clean_Data!I9)),Clean_Data!J9<=Clean_Data!I9,"") | U9: =IF(NOT(ISNUMBER(Clean_Data!L9)),FALSE(),AND(Clean_Data!L9>=0,Clean_Data!L9<=1)) -> FALSE
A10: =Clean_Data!A10 -> TSK-0009 | B10: =Clean_Data!K10="Completed" -> FALSE | C10: =OR(Clean_Data!K10="Not Started",Clean_Data!K10="In Progress",Clean_Data!K10="On Hold") -> TRUE | D10: =AND(ISNUMBER(Clean_Data!I10),Clean_Data!I10<TODAY(),Clean_Data!K10<>"Completed",Clean_Data!K10<>"Cancelled") -> TRUE | E10: =IF(AND(ISNUMBER(Clean_Data!H10),Clean_Data!K10<>"Completed",Clean_Data!K10<>"Cancelled"),TODAY()-Clean_Data!H10,"") -> 608 | F10: =IF(AND(B10=TRUE(),ISNUMBER(Clean_Data!J10),ISNUMBER(Clean_Data!I10)),MAX(0,Clean_Data!J10-Clean_Data!I10),IF(AND(B10=FALSE(),ISNUMBER(Clean_Data!I10),Clean_Data!I10<TODAY(),Clean_Data!K10<>"Cancelled"),MAX(0,TODAY()-Clean_Data!I10),"")) -> 593 | G10: =IF(AND(B10=TRUE(),ISNUMBER(Clean_Data!J10),ISNUMBER(Clean_Data!H10)),Clean_Data!J10-Clean_Data!H10,"") | H10: =IF(AND(ISNUMBER(Clean_Data!J10),ISNUMBER(Clean_Data!H10)),Clean_Data!J10-Clean_Data!H10,IF(ISNUMBER(Clean_Data!H10),TODAY()-Clean_Data!H10,"")) -> 608 | I10: =IF(ISNUMBER(Clean_Data!I10),TEXT(Clean_Data!I10,"YYYY-MM"),"") -> 2024-08 | J10: =IF(ISNUMBER(Clean_Data!H10),TEXT(Clean_Data!H10,"YYYY-MM"),"") -> 2024-08 | K10: =IF(ISNUMBER(Clean_Data!J10),TEXT(Clean_Data!J10,"YYYY-MM"),"") | L10: =IF(ISNUMBER(Clean_Data!H10),YEAR(Clean_Data!H10),"") -> 2024 | M10: =IF(ISNUMBER(Clean_Data!H10),MONTH(Clean_Data!H10),"") -> 8 | N10: =IF(ISNUMBER(Clean_Data!H10),TEXT(Clean_Data!H10,"MMMM"),"") -> August | O10: =D10 -> TRUE | P10: =AND(OR(Clean_Data!F10="High",Clean_Data!F10="Critical"),C10=TRUE()) -> TRUE | Q10: =AND(OR(Clean_Data!F10="High",Clean_Data!F10="Critical"),D10=TRUE()) -> TRUE | R10: =AND(Clean_Data!K10="In Progress",ISNUMBER(Clean_Data!H10),TODAY()-Clean_Data!H10>30) -> FALSE | S10: =IF(B10=TRUE(),IF(AND(ISNUMBER(Clean_Data!N10),ISNUMBER(Clean_Data!M10),Clean_Data!M10>0),IF(Clean_Data!N10<=Clean_Data!M10*1.2,"Healthy","Over Budget"),"N/A"),IF(AND(Clean_Data!K10="In Progress",ISNUMBER(Clean_Data!L10)),IF(Clean_Data!L10>=0.5,"On Track","Slow"),"N/A")) -> N/A | T10: =IF(AND(B10=TRUE(),ISNUMBER(Clean_Data!J10),ISNUMBER(Clean_Data!I10)),Clean_Data!J10<=Clean_Data!I10,"") | U10: =IF(NOT(ISNUMBER(Clean_Data!L10)),FALSE(),AND(Clean_Data!L10>=0,Clean_Data!L10<=1)) -> FALSE
A11: =Clean_Data!A11 -> TSK-0010 | B11: =Clean_Data!K11="Completed" -> FALSE | C11: =OR(Clean_Data!K11="Not Started",Clean_Data!K11="In Progress",Clean_Data!K11="On Hold") -> TRUE | D11: =AND(ISNUMBER(Clean_Data!I11),Clean_Data!I11<TODAY(),Clean_Data!K11<>"Completed",Clean_Data!K11<>"Cancelled") -> TRUE | E11: =IF(AND(ISNUMBER(Clean_Data!H11),Clean_Data!K11<>"Completed",Clean_Data!K11<>"Cancelled"),TODAY()-Clean_Data!H11,"") -> 519 | F11: =IF(AND(B11=TRUE(),ISNUMBER(Clean_Data!J11),ISNUMBER(Clean_Data!I11)),MAX(0,Clean_Data!J11-Clean_Data!I11),IF(AND(B11=FALSE(),ISNUMBER(Clean_Data!I11),Clean_Data!I11<TODAY(),Clean_Data!K11<>"Cancelled"),MAX(0,TODAY()-Clean_Data!I11),"")) -> 502 | G11: =IF(AND(B11=TRUE(),ISNUMBER(Clean_Data!J11),ISNUMBER(Clean_Data!H11)),Clean_Data!J11-Clean_Data!H11,"") | H11: =IF(AND(ISNUMBER(Clean_Data!J11),ISNUMBER(Clean_Data!H11)),Clean_Data!J11-Clean_Data!H11,IF(ISNUMBER(Clean_Data!H11),TODAY()-Clean_Data!H11,"")) -> 519 | I11: =IF(ISNUMBER(Clean_Data!I11),TEXT(Clean_Data!I11,"YYYY-MM"),"") -> 2024-11 | J11: =IF(ISNUMBER(Clean_Data!H11),TEXT(Clean_Data!H11,"YYYY-MM"),"") -> 2024-11 | K11: =IF(ISNUMBER(Clean_Data!J11),TEXT(Clean_Data!J11,"YYYY-MM"),"") | L11: =IF(ISNUMBER(Clean_Data!H11),YEAR(Clean_Data!H11),"") -> 2024 | M11: =IF(ISNUMBER(Clean_Data!H11),MONTH(Clean_Data!H11),"") -> 11 | N11: =IF(ISNUMBER(Clean_Data!H11),TEXT(Clean_Data!H11,"MMMM"),"") -> November | O11: =D11 -> TRUE | P11: =AND(OR(Clean_Data!F11="High",Clean_Data!F11="Critical"),C11=TRUE()) -> TRUE | Q11: =AND(OR(Clean_Data!F11="High",Clean_Data!F11="Critical"),D11=TRUE()) -> TRUE | R11: =AND(Clean_Data!K11="In Progress",ISNUMBER(Clean_Data!H11),TODAY()-Clean_Data!H11>30) -> TRUE | S11: =IF(B11=TRUE(),IF(AND(ISNUMBER(Clean_Data!N11),ISNUMBER(Clean_Data!M11),Clean_Data!M11>0),IF(Clean_Data!N11<=Clean_Data!M11*1.2,"Healthy","Over Budget"),"N/A"),IF(AND(Clean_Data!K11="In Progress",ISNUMBER(Clean_Data!L11)),IF(Clean_Data!L11>=0.5,"On Track","Slow"),"N/A")) -> On Track | T11: =IF(AND(B11=TRUE(),ISNUMBER(Clean_Data!J11),ISNUMBER(Clean_Data!I11)),Clean_Data!J11<=Clean_Data!I11,"") | U11: =IF(NOT(ISNUMBER(Clean_Data!L11)),FALSE(),AND(Clean_Data!L11>=0,Clean_Data!L11<=1)) -> TRUE
A12: =Clean_Data!A12 -> TSK-0011 | B12: =Clean_Data!K12="Completed" -> FALSE | C12: =OR(Clean_Data!K12="Not Started",Clean_Data!K12="In Progress",Clean_Data!K12="On Hold") -> TRUE | D12: =AND(ISNUMBER(Clean_Data!I12),Clean_Data!I12<TODAY(),Clean_Data!K12<>"Completed",Clean_Data!K12<>"Cancelled") -> TRUE | E12: =IF(AND(ISNUMBER(Clean_Data!H12),Clean_Data!K12<>"Completed",Clean_Data!K12<>"Cancelled"),TODAY()-Clean_Data!H12,"") -> 795 | F12: =IF(AND(B12=TRUE(),ISNUMBER(Clean_Data!J12),ISNUMBER(Clean_Data!I12)),MAX(0,Clean_Data!J12-Clean_Data!I12),IF(AND(B12=FALSE(),ISNUMBER(Clean_Data!I12),Clean_Data!I12<TODAY(),Clean_Data!K12<>"Cancelled"),MAX(0,TODAY()-Clean_Data!I12),"")) -> 742 | G12: =IF(AND(B12=TRUE(),ISNUMBER(Clean_Data!J12),ISNUMBER(Clean_Data!H12)),Clean_Data!J12-Clean_Data!H12,"") | H12: =IF(AND(ISNUMBER(Clean_Data!J12),ISNUMBER(Clean_Data!H12)),Clean_Data!J12-Clean_Data!H12,IF(ISNUMBER(Clean_Data!H12),TODAY()-Clean_Data!H12,"")) -> 795 | I12: =IF(ISNUMBER(Clean_Data!I12),TEXT(Clean_Data!I12,"YYYY-MM"),"") -> 2024-04 | J12: =IF(ISNUMBER(Clean_Data!H12),TEXT(Clean_Data!H12,"YYYY-MM"),"") -> 2024-02 | K12: =IF(ISNUMBER(Clean_Data!J12),TEXT(Clean_Data!J12,"YYYY-MM"),"") | L12: =IF(ISNUMBER(Clean_Data!H12),YEAR(Clean_Data!H12),"") -> 2024 | M12: =IF(ISNUMBER(Clean_Data!H12),MONTH(Clean_Data!H12),"") -> 2 | N12: =IF(ISNUMBER(Clean_Data!H12),TEXT(Clean_Data!H12,"MMMM"),"") -> February | O12: =D12 -> TRUE | P12: =AND(OR(Clean_Data!F12="High",Clean_Data!F12="Critical"),C12=TRUE()) -> TRUE | Q12: =AND(OR(Clean_Data!F12="High",Clean_Data!F12="Critical"),D12=TRUE()) -> TRUE | R12: =AND(Clean_Data!K12="In Progress",ISNUMBER(Clean_Data!H12),TODAY()-Clean_Data!H12>30) -> TRUE | S12: =IF(B12=TRUE(),IF(AND(ISNUMBER(Clean_Data!N12),ISNUMBER(Clean_Data!M12),Clean_Data!M12>0),IF(Clean_Data!N12<=Clean_Data!M12*1.2,"Healthy","Over Budget"),"N/A"),IF(AND(Clean_Data!K12="In Progress",ISNUMBER(Clean_Data!L12)),IF(Clean_Data!L12>=0.5,"On Track","Slow"),"N/A")) -> On Track | T12: =IF(AND(B12=TRUE(),ISNUMBER(Clean_Data!J12),ISNUMBER(Clean_Data!I12)),Clean_Data!J12<=Clean_Data!I12,"") | U12: =IF(NOT(ISNUMBER(Clean_Data!L12)),FALSE(),AND(Clean_Data!L12>=0,Clean_Data!L12<=1)) -> TRUE
A13: =Clean_Data!A13 -> TSK-0012 | B13: =Clean_Data!K13="Completed" -> FALSE | C13: =OR(Clean_Data!K13="Not Started",Clean_Data!K13="In Progress",Clean_Data!K13="On Hold") -> TRUE | D13: =AND(ISNUMBER(Clean_Data!I13),Clean_Data!I13<TODAY(),Clean_Data!K13<>"Completed",Clean_Data!K13<>"Cancelled") -> TRUE | E13: =IF(AND(ISNUMBER(Clean_Data!H13),Clean_Data!K13<>"Completed",Clean_Data!K13<>"Cancelled"),TODAY()-Clean_Data!H13,"") -> 599 | F13: =IF(AND(B13=TRUE(),ISNUMBER(Clean_Data!J13),ISNUMBER(Clean_Data!I13)),MAX(0,Clean_Data!J13-Clean_Data!I13),IF(AND(B13=FALSE(),ISNUMBER(Clean_Data!I13),Clean_Data!I13<TODAY(),Clean_Data!K13<>"Cancelled"),MAX(0,TODAY()-Clean_Data!I13),"")) -> 587 | G13: =IF(AND(B13=TRUE(),ISNUMBER(Clean_Data!J13),ISNUMBER(Clean_Data!H13)),Clean_Data!J13-Clean_Data!H13,"") | H13: =IF(AND(ISNUMBER(Clean_Data!J13),ISNUMBER(Clean_Data!H13)),Clean_Data!J13-Clean_Data!H13,IF(ISNUMBER(Clean_Data!H13),TODAY()-Clean_Data!H13,"")) -> 599 | I13: =IF(ISNUMBER(Clean_Data!I13),TEXT(Clean_Data!I13,"YYYY-MM"),"") -> 2024-09 | J13: =IF(ISNUMBER(Clean_Data!H13),TEXT(Clean_Data!H13,"YYYY-MM"),"") -> 2024-08 | K13: =IF(ISNUMBER(Clean_Data!J13),TEXT(Clean_Data!J13,"YYYY-MM"),"") | L13: =IF(ISNUMBER(Clean_Data!H13),YEAR(Clean_Data!H13),"") -> 2024 | M13: =IF(ISNUMBER(Clean_Data!H13),MONTH(Clean_Data!H13),"") -> 8 | N13: =IF(ISNUMBER(Clean_Data!H13),TEXT(Clean_Data!H13,"MMMM"),"") -> August | O13: =D13 -> TRUE | P13: =AND(OR(Clean_Data!F13="High",Clean_Data!F13="Critical"),C13=TRUE()) -> FALSE | Q13: =AND(OR(Clean_Data!F13="High",Clean_Data!F13="Critical"),D13=TRUE()) -> FALSE | R13: =AND(Clean_Data!K13="In Progress",ISNUMBER(Clean_Data!H13),TODAY()-Clean_Data!H13>30) -> TRUE | S13: =IF(B13=TRUE(),IF(AND(ISNUMBER(Clean_Data!N13),ISNUMBER(Clean_Data!M13),Clean_Data!M13>0),IF(Clean_Data!N13<=Clean_Data!M13*1.2,"Healthy","Over Budget"),"N/A"),IF(AND(Clean_Data!K13="In Progress",ISNUMBER(Clean_Data!L13)),IF(Clean_Data!L13>=0.5,"On Track","Slow"),"N/A")) -> Slow | T13: =IF(AND(B13=TRUE(),ISNUMBER(Clean_Data!J13),ISNUMBER(Clean_Data!I13)),Clean_Data!J13<=Clean_Data!I13,"") | U13: =IF(NOT(ISNUMBER(Clean_Data!L13)),FALSE(),AND(Clean_Data!L13>=0,Clean_Data!L13<=1)) -> TRUE
... A121: =Clean_Data!A121 -> TSK-0120 | B121: =Clean_Data!K121="Completed" -> FALSE | C121: =OR(Clean_Data!K121="Not Started",Clean_Data!K121="In Progress",Clean_Data!K121="On Hold") -> FALSE | D121: =AND(ISNUMBER(Clean_Data!I121),Clean_Data!I121<TODAY(),Clean_Data!K121<>"Completed",Clean_Data!K121<>"Cancelled") -> FALSE | E121: =IF(AND(ISNUMBER(Clean_Data!H121),Clean_Data!K121<>"Completed",Clean_Data!K121<>"Cancelled"),TODAY()-Clean_Data!H121,"") | F121: =IF(AND(B121=TRUE(),ISNUMBER(Clean_Data!J121),ISNUMBER(Clean_Data!I121)),MAX(0,Clean_Data!J121-Clean_Data!I121),IF(AND(B121=FALSE(),ISNUMBER(Clean_Data!I121),Clean_Data!I121<TODAY(),Clean_Data!K121<>"Cancelled"),MAX(0,TODAY()-Clean_Data!I121),"")) | G121: =IF(AND(B121=TRUE(),ISNUMBER(Clean_Data!J121),ISNUMBER(Clean_Data!H121)),Clean_Data!J121-Clean_Data!H121,"") | H121: =IF(AND(ISNUMBER(Clean_Data!J121),ISNUMBER(Clean_Data!H121)),Clean_Data!J121-Clean_Data!H121,IF(ISNUMBER(Clean_Data!H121),TODAY()-Clean_Data!H121,"")) -> 642 | I121: =IF(ISNUMBER(Clean_Data!I121),TEXT(Clean_Data!I121,"YYYY-MM"),"") -> 2024-09 | J121: =IF(ISNUMBER(Clean_Data!H121),TEXT(Clean_Data!H121,"YYYY-MM"),"") -> 2024-07 | K121: =IF(ISNUMBER(Clean_Data!J121),TEXT(Clean_Data!J121,"YYYY-MM"),"") | L121: =IF(ISNUMBER(Clean_Data!H121),YEAR(Clean_Data!H121),"") -> 2024 | M121: =IF(ISNUMBER(Clean_Data!H121),MONTH(Clean_Data!H121),"") -> 7 | N121: =IF(ISNUMBER(Clean_Data!H121),TEXT(Clean_Data!H121,"MMMM"),"") -> July | O121: =D121 -> FALSE | P121: =AND(OR(Clean_Data!F121="High",Clean_Data!F121="Critical"),C121=TRUE()) -> FALSE | Q121: =AND(OR(Clean_Data!F121="High",Clean_Data!F121="Critical"),D121=TRUE()) -> FALSE | R121: =AND(Clean_Data!K121="In Progress",ISNUMBER(Clean_Data!H121),TODAY()-Clean_Data!H121>30) -> FALSE | S121: =IF(B121=TRUE(),IF(AND(ISNUMBER(Clean_Data!N121),ISNUMBER(Clean_Data!M121),Clean_Data!M121>0),IF(Clean_Data!N121<=Clean_Data!M121*1.2,"Healthy","Over Budget"),"N/A"),IF(AND(Clean_Data!K121="In Progress",ISNUMBER(Clean_Data!L121)),IF(Clean_Data!L121>=0.5,"On Track","Slow"),"N/A")) -> N/A | T121: =IF(AND(B121=TRUE(),ISNUMBER(Clean_Data!J121),ISNUMBER(Clean_Data!I121)),Clean_Data!J121<=Clean_Data!I121,"") | U121: =IF(NOT(ISNUMBER(Clean_Data!L121)),FALSE(),AND(Clean_Data!L121>=0,Clean_Data!L121<=1)) -> FALSE

Sheet Workload_Analysis
A1: Employee | B1: Assigned Tasks | C1: Open Tasks | D1: Completed Tasks | E1: Total Est Hours | F1: Total Act Hours | G1: Avg Est Hours | H1: Avg Act Hours | I1: Avg Cycle Time | J1: Overdue Tasks | K1: High Priority Tasks | L1: Productivity Score | M1: Capacity Hours | N1: Utilization % | O1: Load Status
A2: Rahul Sharma | B2: =COUNTIFS(Clean_Data!D:D,A2) -> 7 | C2: =COUNTIFS(Clean_Data!D:D,A2,Clean_Data!K:K,"<>Completed",Clean_Data!K:K,"<>Cancelled") -> 2 | D2: =COUNTIFS(Clean_Data!D:D,A2,Clean_Data!K:K,"Completed") -> 4 | E2: =SUMIFS(Clean_Data!M:M,Clean_Data!D:D,A2) -> 227.2 | F2: =SUMIFS(Clean_Data!N:N,Clean_Data!D:D,A2) -> 197.3 | G2: =IFERROR(AVERAGEIFS(Clean_Data!M:M,Clean_Data!D:D,A2),0) -> 32.457143 | H2: =IFERROR(AVERAGEIFS(Clean_Data!N:N,Clean_Data!D:D,A2),0) -> 39.46 | I2: =IFERROR(AVERAGEIFS(Calc_Helper!G:G,Clean_Data!D:D,A2),0) -> 46.5 | J2: =COUNTIFS(Clean_Data!D:D,A2,Calc_Helper!D:D,TRUE()) -> 2 | K2: =COUNTIFS(Clean_Data!D:D,A2,Calc_Helper!P:P,TRUE()) -> 2 | L2: =IFERROR(D2/B2,0) -> 0.57142857 | M2: 160 | N2: =IFERROR(F2/M2,0) -> 1.233125 | O2: =IF(N2>1,"Overloaded",IF(N2>0.8,"High",IF(N2>0.5,"Balanced","Underutilized"))) -> Overloaded
A3: Priya Patel | B3: =COUNTIFS(Clean_Data!D:D,A3) -> 11 | C3: =COUNTIFS(Clean_Data!D:D,A3,Clean_Data!K:K,"<>Completed",Clean_Data!K:K,"<>Cancelled") -> 8 | D3: =COUNTIFS(Clean_Data!D:D,A3,Clean_Data!K:K,"Completed") -> 3 | E3: =SUMIFS(Clean_Data!M:M,Clean_Data!D:D,A3) -> 622.2 | F3: =SUMIFS(Clean_Data!N:N,Clean_Data!D:D,A3) -> 211.5 | G3: =IFERROR(AVERAGEIFS(Clean_Data!M:M,Clean_Data!D:D,A3),0) -> 56.563636 | H3: =IFERROR(AVERAGEIFS(Clean_Data!N:N,Clean_Data!D:D,A3),0) -> 30.214286 | I3: =IFERROR(AVERAGEIFS(Calc_Helper!G:G,Clean_Data!D:D,A3),0) -> 36.333333 | J3: =COUNTIFS(Clean_Data!D:D,A3,Calc_Helper!D:D,TRUE()) -> 8 | K3: =COUNTIFS(Clean_Data!D:D,A3,Calc_Helper!P:P,TRUE()) -> 2 | L3: =IFERROR(D3/B3,0) -> 0.27272727 | M3: 160 | N3: =IFERROR(F3/M3,0) -> 1.321875 | O3: =IF(N3>1,"Overloaded",IF(N3>0.8,"High",IF(N3>0.5,"Balanced","Underutilized"))) -> Overloaded
